>>> from market import app, db
>>> from market.models import Item
>>> with app.app_context():
...     item1 = Item(name="Iphone15", price=999, barcode="9567423273", description="desc")
...     db.session.add(item1)
...     db.session.commit()
...
Traceback (most recent call last):
  File "C:\Program Files\Python312\Lib\site-packages\sqlalchemy\engine\base.py", line 1967, in _exec_single_context
    self.dialect.do_execute(
  File "C:\Program Files\Python312\Lib\site-packages\sqlalchemy\engine\default.py", line 941, in do_execute
    cursor.execute(statement, parameters)
sqlite3.OperationalError: no such table: item

The above exception was the direct cause of the following exception:

Traceback (most recent call last):
  File "<stdin>", line 4, in <module>
  File "C:\Program Files\Python312\Lib\site-packages\sqlalchemy\orm\scoping.py", line 597, in commit
    return self._proxied.commit()
           ^^^^^^^^^^^^^^^^^^^^^^
  File "C:\Program Files\Python312\Lib\site-packages\sqlalchemy\orm\session.py", line 2028, in commit
    trans.commit(_to_root=True)
  File "<string>", line 2, in commit
  File "C:\Program Files\Python312\Lib\site-packages\sqlalchemy\orm\state_changes.py", line 139, in _go
    ret_value = fn(self, *arg, **kw)
                ^^^^^^^^^^^^^^^^^^^^
  File "C:\Program Files\Python312\Lib\site-packages\sqlalchemy\orm\session.py", line 1313, in commit
    self._prepare_impl()
  File "<string>", line 2, in _prepare_impl
  File "C:\Program Files\Python312\Lib\site-packages\sqlalchemy\orm\state_changes.py", line 139, in _go
    ret_value = fn(self, *arg, **kw)
                ^^^^^^^^^^^^^^^^^^^^
  File "C:\Program Files\Python312\Lib\site-packages\sqlalchemy\orm\session.py", line 1288, in _prepare_impl
    self.session.flush()
  File "C:\Program Files\Python312\Lib\site-packages\sqlalchemy\orm\session.py", line 4352, in flush
    self._flush(objects)
  File "C:\Program Files\Python312\Lib\site-packages\sqlalchemy\orm\session.py", line 4487, in _flush
    with util.safe_reraise():
  File "C:\Program Files\Python312\Lib\site-packages\sqlalchemy\util\langhelpers.py", line 146, in __exit__
    raise exc_value.with_traceback(exc_tb)
  File "C:\Program Files\Python312\Lib\site-packages\sqlalchemy\orm\session.py", line 4448, in _flush
    flush_context.execute()
  File "C:\Program Files\Python312\Lib\site-packages\sqlalchemy\orm\unitofwork.py", line 466, in execute
    rec.execute(self)
  File "C:\Program Files\Python312\Lib\site-packages\sqlalchemy\orm\unitofwork.py", line 642, in execute
    util.preloaded.orm_persistence.save_obj(
  File "C:\Program Files\Python312\Lib\site-packages\sqlalchemy\orm\persistence.py", line 93, in save_obj
    _emit_insert_statements(
  File "C:\Program Files\Python312\Lib\site-packages\sqlalchemy\orm\persistence.py", line 1233, in _emit_insert_statements
    result = connection.execute(
             ^^^^^^^^^^^^^^^^^^^
  File "C:\Program Files\Python312\Lib\site-packages\sqlalchemy\engine\base.py", line 1418, in execute
    return meth(
           ^^^^^
  File "C:\Program Files\Python312\Lib\site-packages\sqlalchemy\sql\elements.py", line 515, in _execute_on_connection
    return connection._execute_clauseelement(
           ^^^^^^^^^^^^^^^^^^^^^^^^^^^^^^^^^^
  File "C:\Program Files\Python312\Lib\site-packages\sqlalchemy\engine\base.py", line 1640, in _execute_clauseelement
    ret = self._execute_context(
          ^^^^^^^^^^^^^^^^^^^^^^
  File "C:\Program Files\Python312\Lib\site-packages\sqlalchemy\engine\base.py", line 1846, in _execute_context
    return self._exec_single_context(
           ^^^^^^^^^^^^^^^^^^^^^^^^^^
  File "C:\Program Files\Python312\Lib\site-packages\sqlalchemy\engine\base.py", line 1986, in _exec_single_context
    self._handle_dbapi_exception(
  File "C:\Program Files\Python312\Lib\site-packages\sqlalchemy\engine\base.py", line 2355, in _handle_dbapi_exception
    raise sqlalchemy_exception.with_traceback(exc_info[2]) from e
  File "C:\Program Files\Python312\Lib\site-packages\sqlalchemy\engine\base.py", line 1967, in _exec_single_context
    self.dialect.do_execute(
  File "C:\Program Files\Python312\Lib\site-packages\sqlalchemy\engine\default.py", line 941, in do_execute
    cursor.execute(statement, parameters)
sqlalchemy.exc.OperationalError: (sqlite3.OperationalError) no such table: item
[SQL: INSERT INTO item (name, price, barcode, description) VALUES (?, ?, ?, ?)]
[parameters: ('Iphone15', 999, '9567423273', 'desc')]
(Background on this error at: https://sqlalche.me/e/20/e3q8)

















>>> from market.models import db
>>> db.drop_all()
Traceback (most recent call last):
  File "<stdin>", line 1, in <module>
  File "C:\Program Files\Python312\Lib\site-packages\flask_sqlalchemy\extension.py", line 917, in drop_all
    self._call_for_binds(bind_key, "drop_all")
  File "C:\Program Files\Python312\Lib\site-packages\flask_sqlalchemy\extension.py", line 871, in _call_for_binds
    engine = self.engines[key]
             ^^^^^^^^^^^^
  File "C:\Program Files\Python312\Lib\site-packages\flask_sqlalchemy\extension.py", line 687, in engines
    app = current_app._get_current_object()  # type: ignore[attr-defined]
          ^^^^^^^^^^^^^^^^^^^^^^^^^^^^^^^^^
  File "C:\Program Files\Python312\Lib\site-packages\werkzeug\local.py", line 519, in _get_current_object
    raise RuntimeError(unbound_message) from None
RuntimeError: Working outside of application context.

This typically means that you attempted to use functionality that needed
the current application. To solve this, set up an application context
with app.app_context(). See the documentation for more information.
>>> db.drop_all()
