>>> from market import app, db
>>> from market.models import Item
>>> with app.app_context():
...     item1 = Item(name="Iphone15", price=999, barcode="9567423273", description="desc")
...     db.session.add(item1)
...     db.session.commit()
...
Traceback (most recent call last):
  File "C:\Program Files\Python312\Lib\site-packages\sqlalchemy\engine\base.py", line 1967, in _exec_single_context
    self.dialect.do_execute(
  File "C:\Program Files\Python312\Lib\site-packages\sqlalchemy\engine\default.py", line 941, in do_execute
    cursor.execute(statement, parameters)
sqlite3.OperationalError: no such table: item

The above exception was the direct cause of the following exception:

Traceback (most recent call last):
  File "<stdin>", line 4, in <module>
  File "C:\Program Files\Python312\Lib\site-packages\sqlalchemy\orm\scoping.py", line 597, in commit
    return self._proxied.commit()
           ^^^^^^^^^^^^^^^^^^^^^^
  File "C:\Program Files\Python312\Lib\site-packages\sqlalchemy\orm\session.py", line 2028, in commit
    trans.commit(_to_root=True)
  File "<string>", line 2, in commit
  File "C:\Program Files\Python312\Lib\site-packages\sqlalchemy\orm\state_changes.py", line 139, in _go
    ret_value = fn(self, *arg, **kw)
                ^^^^^^^^^^^^^^^^^^^^
  File "C:\Program Files\Python312\Lib\site-packages\sqlalchemy\orm\session.py", line 1313, in commit
    self._prepare_impl()
  File "<string>", line 2, in _prepare_impl
  File "C:\Program Files\Python312\Lib\site-packages\sqlalchemy\orm\state_changes.py", line 139, in _go
    ret_value = fn(self, *arg, **kw)
                ^^^^^^^^^^^^^^^^^^^^
  File "C:\Program Files\Python312\Lib\site-packages\sqlalchemy\orm\session.py", line 1288, in _prepare_impl
    self.session.flush()
  File "C:\Program Files\Python312\Lib\site-packages\sqlalchemy\orm\session.py", line 4352, in flush
    self._flush(objects)
  File "C:\Program Files\Python312\Lib\site-packages\sqlalchemy\orm\session.py", line 4487, in _flush
    with util.safe_reraise():
  File "C:\Program Files\Python312\Lib\site-packages\sqlalchemy\util\langhelpers.py", line 146, in __exit__
    raise exc_value.with_traceback(exc_tb)
  File "C:\Program Files\Python312\Lib\site-packages\sqlalchemy\orm\session.py", line 4448, in _flush
    flush_context.execute()
  File "C:\Program Files\Python312\Lib\site-packages\sqlalchemy\orm\unitofwork.py", line 466, in execute
    rec.execute(self)
  File "C:\Program Files\Python312\Lib\site-packages\sqlalchemy\orm\unitofwork.py", line 642, in execute
    util.preloaded.orm_persistence.save_obj(
  File "C:\Program Files\Python312\Lib\site-packages\sqlalchemy\orm\persistence.py", line 93, in save_obj
    _emit_insert_statements(
  File "C:\Program Files\Python312\Lib\site-packages\sqlalchemy\orm\persistence.py", line 1233, in _emit_insert_statements
    result = connection.execute(
             ^^^^^^^^^^^^^^^^^^^
  File "C:\Program Files\Python312\Lib\site-packages\sqlalchemy\engine\base.py", line 1418, in execute
    return meth(
           ^^^^^
  File "C:\Program Files\Python312\Lib\site-packages\sqlalchemy\sql\elements.py", line 515, in _execute_on_connection
    return connection._execute_clauseelement(
           ^^^^^^^^^^^^^^^^^^^^^^^^^^^^^^^^^^
  File "C:\Program Files\Python312\Lib\site-packages\sqlalchemy\engine\base.py", line 1640, in _execute_clauseelement
    ret = self._execute_context(
          ^^^^^^^^^^^^^^^^^^^^^^
  File "C:\Program Files\Python312\Lib\site-packages\sqlalchemy\engine\base.py", line 1846, in _execute_context
    return self._exec_single_context(
           ^^^^^^^^^^^^^^^^^^^^^^^^^^
  File "C:\Program Files\Python312\Lib\site-packages\sqlalchemy\engine\base.py", line 1986, in _exec_single_context
    self._handle_dbapi_exception(
  File "C:\Program Files\Python312\Lib\site-packages\sqlalchemy\engine\base.py", line 2355, in _handle_dbapi_exception
    raise sqlalchemy_exception.with_traceback(exc_info[2]) from e
  File "C:\Program Files\Python312\Lib\site-packages\sqlalchemy\engine\base.py", line 1967, in _exec_single_context
    self.dialect.do_execute(
  File "C:\Program Files\Python312\Lib\site-packages\sqlalchemy\engine\default.py", line 941, in do_execute
    cursor.execute(statement, parameters)
sqlalchemy.exc.OperationalError: (sqlite3.OperationalError) no such table: item
[SQL: INSERT INTO item (name, price, barcode, description) VALUES (?, ?, ?, ?)]
[parameters: ('Iphone15', 999, '9567423273', 'desc')]
(Background on this error at: https://sqlalche.me/e/20/e3q8)













ERRRORRRR --- 30 Aug 2024

DatabaseError
sqlalchemy.exc.DatabaseError: (sqlite3.DatabaseError) database disk image is malformed
[SQL: SELECT user.id AS user_id, user.username AS user_username, user.email_address AS user_email_address, user.password_hash AS user_password_hash, user.budget AS user_budget 
FROM user 
WHERE user.username = ?
 LIMIT ? OFFSET ?]
[parameters: ('king', 1, 0)]
(Background on this error at: https://sqlalche.me/e/20/4xp6)

Traceback (most recent call last)
File "C:\Program Files\Python312\Lib\site-packages\sqlalchemy\engine\base.py", line 1967, in _exec_single_context
self.dialect.do_execute(
^
File "C:\Program Files\Python312\Lib\site-packages\sqlalchemy\engine\default.py", line 941, in do_execute
cursor.execute(statement, parameters)
^^^^^^^^^^^^^^^^^^^^^^^^^^^^^^^^^^^^^
The above exception was the direct cause of the following exception:
File "C:\Program Files\Python312\Lib\site-packages\flask\app.py", line 1498, in __call__
return self.wsgi_app(environ, start_response)
       ^^^^^^^^^^^^^^^^^^^^^^^^^^^^^^^^^^^^^^
File "C:\Program Files\Python312\Lib\site-packages\flask\app.py", line 1476, in wsgi_app
response = self.handle_exception(e)
           ^^^^^^^^^^^^^^^^^^^^^^^^
File "C:\Program Files\Python312\Lib\site-packages\flask\app.py", line 1473, in wsgi_app
response = self.full_dispatch_request()
           ^^^^^^^^^^^^^^^^^^^^^^^^^^^^
File "C:\Program Files\Python312\Lib\site-packages\flask\app.py", line 882, in full_dispatch_request
rv = self.handle_user_exception(e)
     ^^^^^^^^^^^^^^^^^^^^^^^^^^^^^
File "C:\Program Files\Python312\Lib\site-packages\flask\app.py", line 880, in full_dispatch_request
rv = self.dispatch_request()
     ^^^^^^^^^^^^^^^^^^^^^^^
File "C:\Program Files\Python312\Lib\site-packages\flask\app.py", line 865, in dispatch_request
return self.ensure_sync(self.view_functions[rule.endpoint])(**view_args)  # type: ignore[no-any-return]
       ^^^^^^^^^^^^^^^^^^^^^^^^^^^^^^^^^^^^^^^^^^^^^^^^^^^^^^^^^^^^^^^^^
File "C:\Python312\00Flask\FlaskMarket\market\routes.py", line 38, in login_page
attempted_user = User.query.filter_by(username = form.username.data).first()
                 ^^^^^^^^^^^^^^^^^^^^^^^^^^^^^^^^^^^^^^^^^^^^^^^^^^^^^^^^^^^
File "C:\Program Files\Python312\Lib\site-packages\sqlalchemy\orm\query.py", line 2728, in first
return self.limit(1)._iter().first()  # type: ignore
       ^^^^^^^^^^^^^^^^^^^^^
File "C:\Program Files\Python312\Lib\site-packages\sqlalchemy\orm\query.py", line 2827, in _iter
result: Union[ScalarResult[_T], Result[_T]] = self.session.execute(
                                              
File "C:\Program Files\Python312\Lib\site-packages\sqlalchemy\orm\session.py", line 2362, in execute
return self._execute_internal(
       
File "C:\Program Files\Python312\Lib\site-packages\sqlalchemy\orm\session.py", line 2247, in _execute_internal
result: Result[Any] = compile_state_cls.orm_execute_statement(
                      
File "C:\Program Files\Python312\Lib\site-packages\sqlalchemy\orm\context.py", line 293, in orm_execute_statement
result = conn.execute(
         
File "C:\Program Files\Python312\Lib\site-packages\sqlalchemy\engine\base.py", line 1418, in execute
return meth(
       
File "C:\Program Files\Python312\Lib\site-packages\sqlalchemy\sql\elements.py", line 515, in _execute_on_connection
return connection._execute_clauseelement(
       
File "C:\Program Files\Python312\Lib\site-packages\sqlalchemy\engine\base.py", line 1640, in _execute_clauseelement
ret = self._execute_context(
      
File "C:\Program Files\Python312\Lib\site-packages\sqlalchemy\engine\base.py", line 1846, in _execute_context
return self._exec_single_context(
       
File "C:\Program Files\Python312\Lib\site-packages\sqlalchemy\engine\base.py", line 1986, in _exec_single_context
self._handle_dbapi_exception(
^
File "C:\Program Files\Python312\Lib\site-packages\sqlalchemy\engine\base.py", line 2355, in _handle_dbapi_exception
raise sqlalchemy_exception.with_traceback(exc_info[2]) from e
^^^^^^^^^^^^^^^^^^^^^^^^^^^^^^^^^^^^^^^^^^^^^^^^^^^^^^^^^^^^^
File "C:\Program Files\Python312\Lib\site-packages\sqlalchemy\engine\base.py", line 1967, in _exec_single_context
self.dialect.do_execute(
^
File "C:\Program Files\Python312\Lib\site-packages\sqlalchemy\engine\default.py", line 941, in do_execute
cursor.execute(statement, parameters)
^^^^^^^^^^^^^^^^^^^^^^^^^^^^^^^^^^^^^
sqlalchemy.exc.DatabaseError: (sqlite3.DatabaseError) database disk image is malformed
[SQL: SELECT user.id AS user_id, user.username AS user_username, user.email_address AS user_email_address, user.password_hash AS user_password_hash, user.budget AS user_budget
FROM user
WHERE user.username = ?
LIMIT ? OFFSET ?]
[parameters: ('king', 1, 0)]
(Background on this error at: https://sqlalche.me/e/20/4xp6)
The debugger caught an exception in your WSGI application. You can now look at the traceback which led to the error.
To switch between the interactive traceback and the plaintext one, you can click on the "Traceback" headline. From the text traceback you can also create a paste of it. For code execution mouse-over the frame you want to debug and click on the console icon on the right side.

You can execute arbitrary Python code in the stack frames and there are some extra helpers available for introspection:

dump() shows all variables in the frame
dump(obj) dumps all that's known about the object
